Traceback (most recent call last):
  File "C:\Users\Scott\AppData\Local\Programs\Python\Python311\Lib\site-packages\urllib3\connection.py", line 198, in _new_conn
    sock = connection.create_connection(
           ^^^^^^^^^^^^^^^^^^^^^^^^^^^^^
  File "C:\Users\Scott\AppData\Local\Programs\Python\Python311\Lib\site-packages\urllib3\util\connection.py", line 60, in create_connection
    for res in socket.getaddrinfo(host, port, family, socket.SOCK_STREAM):
               ^^^^^^^^^^^^^^^^^^^^^^^^^^^^^^^^^^^^^^^^^^^^^^^^^^^^^^^^^^
  File "C:\Users\Scott\AppData\Local\Programs\Python\Python311\Lib\socket.py", line 962, in getaddrinfo
    for res in _socket.getaddrinfo(host, port, family, type, proto, flags):
               ^^^^^^^^^^^^^^^^^^^^^^^^^^^^^^^^^^^^^^^^^^^^^^^^^^^^^^^^^^^
socket.gaierror: [Errno 11001] getaddrinfo failed

The above exception was the direct cause of the following exception:

Traceback (most recent call last):
  File "C:\Users\Scott\AppData\Local\Programs\Python\Python311\Lib\site-packages\urllib3\connectionpool.py", line 787, in urlopen
    response = self._make_request(
               ^^^^^^^^^^^^^^^^^^^
  File "C:\Users\Scott\AppData\Local\Programs\Python\Python311\Lib\site-packages\urllib3\connectionpool.py", line 488, in _make_request
    raise new_e
  File "C:\Users\Scott\AppData\Local\Programs\Python\Python311\Lib\site-packages\urllib3\connectionpool.py", line 464, in _make_request
    self._validate_conn(conn)
  File "C:\Users\Scott\AppData\Local\Programs\Python\Python311\Lib\site-packages\urllib3\connectionpool.py", line 1093, in _validate_conn
    conn.connect()
  File "C:\Users\Scott\AppData\Local\Programs\Python\Python311\Lib\site-packages\urllib3\connection.py", line 704, in connect
    self.sock = sock = self._new_conn()
                       ^^^^^^^^^^^^^^^^
  File "C:\Users\Scott\AppData\Local\Programs\Python\Python311\Lib\site-packages\urllib3\connection.py", line 205, in _new_conn
    raise NameResolutionError(self.host, self, e) from e
urllib3.exceptions.NameResolutionError: <urllib3.connection.HTTPSConnection object at 0x0000020C89D0DD90>: Failed to resolve 'akatsuki.gg' ([Errno 11001] getaddrinfo failed)

The above exception was the direct cause of the following exception:

Traceback (most recent call last):
  File "C:\Users\Scott\AppData\Local\Programs\Python\Python311\Lib\site-packages\requests\adapters.py", line 667, in send
    resp = conn.urlopen(
           ^^^^^^^^^^^^^
  File "C:\Users\Scott\AppData\Local\Programs\Python\Python311\Lib\site-packages\urllib3\connectionpool.py", line 841, in urlopen
    retries = retries.increment(
              ^^^^^^^^^^^^^^^^^^
  File "C:\Users\Scott\AppData\Local\Programs\Python\Python311\Lib\site-packages\urllib3\util\retry.py", line 519, in increment
    raise MaxRetryError(_pool, url, reason) from reason  # type: ignore[arg-type]
    ^^^^^^^^^^^^^^^^^^^^^^^^^^^^^^^^^^^^^^^^^^^^^^^^^^^
urllib3.exceptions.MaxRetryError: HTTPSConnectionPool(host='akatsuki.gg', port=443): Max retries exceeded with url: /api/v1/users/scores/first?mode=0&p=1&l=100&rx=1&id=81870 (Caused by NameResolutionError("<urllib3.connection.HTTPSConnection object at 0x0000020C89D0DD90>: Failed to resolve 'akatsuki.gg' ([Errno 11001] getaddrinfo failed)"))

During handling of the above exception, another exception occurred:

Traceback (most recent call last):
  File "C:\Users\Scott\Documents\OsuCoding\osuTasks\trackFirstPlaces.py", line 103, in <module>
    main()
  File "C:\Users\Scott\Documents\OsuCoding\osuTasks\trackFirstPlaces.py", line 63, in main
    currentFirstPlaceDict = getAllFirstPlaces()
                            ^^^^^^^^^^^^^^^^^^^
  File "C:\Users\Scott\Documents\OsuCoding\osuTasks\trackFirstPlaces.py", line 41, in getAllFirstPlaces
    firstPlaces = requests.get(url).json()
                  ^^^^^^^^^^^^^^^^^
  File "C:\Users\Scott\AppData\Local\Programs\Python\Python311\Lib\site-packages\requests\api.py", line 73, in get
    return request("get", url, params=params, **kwargs)
           ^^^^^^^^^^^^^^^^^^^^^^^^^^^^^^^^^^^^^^^^^^^^
  File "C:\Users\Scott\AppData\Local\Programs\Python\Python311\Lib\site-packages\requests\api.py", line 59, in request
    return session.request(method=method, url=url, **kwargs)
           ^^^^^^^^^^^^^^^^^^^^^^^^^^^^^^^^^^^^^^^^^^^^^^^^^
  File "C:\Users\Scott\AppData\Local\Programs\Python\Python311\Lib\site-packages\requests\sessions.py", line 589, in request
    resp = self.send(prep, **send_kwargs)
           ^^^^^^^^^^^^^^^^^^^^^^^^^^^^^^
  File "C:\Users\Scott\AppData\Local\Programs\Python\Python311\Lib\site-packages\requests\sessions.py", line 703, in send
    r = adapter.send(request, **kwargs)
        ^^^^^^^^^^^^^^^^^^^^^^^^^^^^^^^
  File "C:\Users\Scott\AppData\Local\Programs\Python\Python311\Lib\site-packages\requests\adapters.py", line 700, in send
    raise ConnectionError(e, request=request)
requests.exceptions.ConnectionError: HTTPSConnectionPool(host='akatsuki.gg', port=443): Max retries exceeded with url: /api/v1/users/scores/first?mode=0&p=1&l=100&rx=1&id=81870 (Caused by NameResolutionError("<urllib3.connection.HTTPSConnection object at 0x0000020C89D0DD90>: Failed to resolve 'akatsuki.gg' ([Errno 11001] getaddrinfo failed)"))
Traceback (most recent call last):
  File "C:\Users\Scott\AppData\Local\Programs\Python\Python311\Lib\site-packages\urllib3\connection.py", line 198, in _new_conn
    sock = connection.create_connection(
           ^^^^^^^^^^^^^^^^^^^^^^^^^^^^^
  File "C:\Users\Scott\AppData\Local\Programs\Python\Python311\Lib\site-packages\urllib3\util\connection.py", line 60, in create_connection
    for res in socket.getaddrinfo(host, port, family, socket.SOCK_STREAM):
               ^^^^^^^^^^^^^^^^^^^^^^^^^^^^^^^^^^^^^^^^^^^^^^^^^^^^^^^^^^
  File "C:\Users\Scott\AppData\Local\Programs\Python\Python311\Lib\socket.py", line 962, in getaddrinfo
    for res in _socket.getaddrinfo(host, port, family, type, proto, flags):
               ^^^^^^^^^^^^^^^^^^^^^^^^^^^^^^^^^^^^^^^^^^^^^^^^^^^^^^^^^^^
socket.gaierror: [Errno 11001] getaddrinfo failed

The above exception was the direct cause of the following exception:

Traceback (most recent call last):
  File "C:\Users\Scott\AppData\Local\Programs\Python\Python311\Lib\site-packages\urllib3\connectionpool.py", line 787, in urlopen
    response = self._make_request(
               ^^^^^^^^^^^^^^^^^^^
  File "C:\Users\Scott\AppData\Local\Programs\Python\Python311\Lib\site-packages\urllib3\connectionpool.py", line 488, in _make_request
    raise new_e
  File "C:\Users\Scott\AppData\Local\Programs\Python\Python311\Lib\site-packages\urllib3\connectionpool.py", line 464, in _make_request
    self._validate_conn(conn)
  File "C:\Users\Scott\AppData\Local\Programs\Python\Python311\Lib\site-packages\urllib3\connectionpool.py", line 1093, in _validate_conn
    conn.connect()
  File "C:\Users\Scott\AppData\Local\Programs\Python\Python311\Lib\site-packages\urllib3\connection.py", line 704, in connect
    self.sock = sock = self._new_conn()
                       ^^^^^^^^^^^^^^^^
  File "C:\Users\Scott\AppData\Local\Programs\Python\Python311\Lib\site-packages\urllib3\connection.py", line 205, in _new_conn
    raise NameResolutionError(self.host, self, e) from e
urllib3.exceptions.NameResolutionError: <urllib3.connection.HTTPSConnection object at 0x000001BA44FDE7D0>: Failed to resolve 'akatsuki.gg' ([Errno 11001] getaddrinfo failed)

The above exception was the direct cause of the following exception:

Traceback (most recent call last):
  File "C:\Users\Scott\AppData\Local\Programs\Python\Python311\Lib\site-packages\requests\adapters.py", line 667, in send
    resp = conn.urlopen(
           ^^^^^^^^^^^^^
  File "C:\Users\Scott\AppData\Local\Programs\Python\Python311\Lib\site-packages\urllib3\connectionpool.py", line 841, in urlopen
    retries = retries.increment(
              ^^^^^^^^^^^^^^^^^^
  File "C:\Users\Scott\AppData\Local\Programs\Python\Python311\Lib\site-packages\urllib3\util\retry.py", line 519, in increment
    raise MaxRetryError(_pool, url, reason) from reason  # type: ignore[arg-type]
    ^^^^^^^^^^^^^^^^^^^^^^^^^^^^^^^^^^^^^^^^^^^^^^^^^^^
urllib3.exceptions.MaxRetryError: HTTPSConnectionPool(host='akatsuki.gg', port=443): Max retries exceeded with url: /api/v1/users/scores/first?mode=0&p=1&l=100&rx=1&id=81870 (Caused by NameResolutionError("<urllib3.connection.HTTPSConnection object at 0x000001BA44FDE7D0>: Failed to resolve 'akatsuki.gg' ([Errno 11001] getaddrinfo failed)"))

During handling of the above exception, another exception occurred:

Traceback (most recent call last):
  File "C:\Users\Scott\Documents\OsuCoding\osuTasks\trackFirstPlaces.py", line 103, in <module>
    main()
  File "C:\Users\Scott\Documents\OsuCoding\osuTasks\trackFirstPlaces.py", line 63, in main
    currentFirstPlaceDict = getAllFirstPlaces()
                            ^^^^^^^^^^^^^^^^^^^
  File "C:\Users\Scott\Documents\OsuCoding\osuTasks\trackFirstPlaces.py", line 41, in getAllFirstPlaces
    firstPlaces = requests.get(url).json()
                  ^^^^^^^^^^^^^^^^^
  File "C:\Users\Scott\AppData\Local\Programs\Python\Python311\Lib\site-packages\requests\api.py", line 73, in get
    return request("get", url, params=params, **kwargs)
           ^^^^^^^^^^^^^^^^^^^^^^^^^^^^^^^^^^^^^^^^^^^^
  File "C:\Users\Scott\AppData\Local\Programs\Python\Python311\Lib\site-packages\requests\api.py", line 59, in request
    return session.request(method=method, url=url, **kwargs)
           ^^^^^^^^^^^^^^^^^^^^^^^^^^^^^^^^^^^^^^^^^^^^^^^^^
  File "C:\Users\Scott\AppData\Local\Programs\Python\Python311\Lib\site-packages\requests\sessions.py", line 589, in request
    resp = self.send(prep, **send_kwargs)
           ^^^^^^^^^^^^^^^^^^^^^^^^^^^^^^
  File "C:\Users\Scott\AppData\Local\Programs\Python\Python311\Lib\site-packages\requests\sessions.py", line 703, in send
    r = adapter.send(request, **kwargs)
        ^^^^^^^^^^^^^^^^^^^^^^^^^^^^^^^
  File "C:\Users\Scott\AppData\Local\Programs\Python\Python311\Lib\site-packages\requests\adapters.py", line 700, in send
    raise ConnectionError(e, request=request)
requests.exceptions.ConnectionError: HTTPSConnectionPool(host='akatsuki.gg', port=443): Max retries exceeded with url: /api/v1/users/scores/first?mode=0&p=1&l=100&rx=1&id=81870 (Caused by NameResolutionError("<urllib3.connection.HTTPSConnection object at 0x000001BA44FDE7D0>: Failed to resolve 'akatsuki.gg' ([Errno 11001] getaddrinfo failed)"))
Traceback (most recent call last):
  File "C:\Users\Scott\AppData\Local\Programs\Python\Python311\Lib\site-packages\requests\models.py", line 974, in json
    return complexjson.loads(self.text, **kwargs)
           ^^^^^^^^^^^^^^^^^^^^^^^^^^^^^^^^^^^^^^
  File "C:\Users\Scott\AppData\Local\Programs\Python\Python311\Lib\json\__init__.py", line 346, in loads
    return _default_decoder.decode(s)
           ^^^^^^^^^^^^^^^^^^^^^^^^^^
  File "C:\Users\Scott\AppData\Local\Programs\Python\Python311\Lib\json\decoder.py", line 337, in decode
    obj, end = self.raw_decode(s, idx=_w(s, 0).end())
               ^^^^^^^^^^^^^^^^^^^^^^^^^^^^^^^^^^^^^^
  File "C:\Users\Scott\AppData\Local\Programs\Python\Python311\Lib\json\decoder.py", line 355, in raw_decode
    raise JSONDecodeError("Expecting value", s, err.value) from None
json.decoder.JSONDecodeError: Expecting value: line 1 column 1 (char 0)

During handling of the above exception, another exception occurred:

Traceback (most recent call last):
  File "C:\Users\Scott\Documents\OsuCoding\osuTasks\trackFirstPlaces.py", line 103, in <module>
    main()
  File "C:\Users\Scott\Documents\OsuCoding\osuTasks\trackFirstPlaces.py", line 63, in main
    currentFirstPlaceDict = getAllFirstPlaces()
                            ^^^^^^^^^^^^^^^^^^^
  File "C:\Users\Scott\Documents\OsuCoding\osuTasks\trackFirstPlaces.py", line 41, in getAllFirstPlaces
    firstPlaces = requests.get(url).json()
                  ^^^^^^^^^^^^^^^^^^^^^^^^
  File "C:\Users\Scott\AppData\Local\Programs\Python\Python311\Lib\site-packages\requests\models.py", line 978, in json
    raise RequestsJSONDecodeError(e.msg, e.doc, e.pos)
requests.exceptions.JSONDecodeError: Expecting value: line 1 column 1 (char 0)
Traceback (most recent call last):
  File "C:\Users\Scott\AppData\Local\Programs\Python\Python311\Lib\site-packages\urllib3\connection.py", line 198, in _new_conn
    sock = connection.create_connection(
           ^^^^^^^^^^^^^^^^^^^^^^^^^^^^^
  File "C:\Users\Scott\AppData\Local\Programs\Python\Python311\Lib\site-packages\urllib3\util\connection.py", line 60, in create_connection
    for res in socket.getaddrinfo(host, port, family, socket.SOCK_STREAM):
               ^^^^^^^^^^^^^^^^^^^^^^^^^^^^^^^^^^^^^^^^^^^^^^^^^^^^^^^^^^
  File "C:\Users\Scott\AppData\Local\Programs\Python\Python311\Lib\socket.py", line 962, in getaddrinfo
    for res in _socket.getaddrinfo(host, port, family, type, proto, flags):
               ^^^^^^^^^^^^^^^^^^^^^^^^^^^^^^^^^^^^^^^^^^^^^^^^^^^^^^^^^^^
socket.gaierror: [Errno 11001] getaddrinfo failed

The above exception was the direct cause of the following exception:

Traceback (most recent call last):
  File "C:\Users\Scott\AppData\Local\Programs\Python\Python311\Lib\site-packages\urllib3\connectionpool.py", line 787, in urlopen
    response = self._make_request(
               ^^^^^^^^^^^^^^^^^^^
  File "C:\Users\Scott\AppData\Local\Programs\Python\Python311\Lib\site-packages\urllib3\connectionpool.py", line 488, in _make_request
    raise new_e
  File "C:\Users\Scott\AppData\Local\Programs\Python\Python311\Lib\site-packages\urllib3\connectionpool.py", line 464, in _make_request
    self._validate_conn(conn)
  File "C:\Users\Scott\AppData\Local\Programs\Python\Python311\Lib\site-packages\urllib3\connectionpool.py", line 1093, in _validate_conn
    conn.connect()
  File "C:\Users\Scott\AppData\Local\Programs\Python\Python311\Lib\site-packages\urllib3\connection.py", line 704, in connect
    self.sock = sock = self._new_conn()
                       ^^^^^^^^^^^^^^^^
  File "C:\Users\Scott\AppData\Local\Programs\Python\Python311\Lib\site-packages\urllib3\connection.py", line 205, in _new_conn
    raise NameResolutionError(self.host, self, e) from e
urllib3.exceptions.NameResolutionError: <urllib3.connection.HTTPSConnection object at 0x00000184CCB71B50>: Failed to resolve 'akatsuki.gg' ([Errno 11001] getaddrinfo failed)

The above exception was the direct cause of the following exception:

Traceback (most recent call last):
  File "C:\Users\Scott\AppData\Local\Programs\Python\Python311\Lib\site-packages\requests\adapters.py", line 667, in send
    resp = conn.urlopen(
           ^^^^^^^^^^^^^
  File "C:\Users\Scott\AppData\Local\Programs\Python\Python311\Lib\site-packages\urllib3\connectionpool.py", line 841, in urlopen
    retries = retries.increment(
              ^^^^^^^^^^^^^^^^^^
  File "C:\Users\Scott\AppData\Local\Programs\Python\Python311\Lib\site-packages\urllib3\util\retry.py", line 519, in increment
    raise MaxRetryError(_pool, url, reason) from reason  # type: ignore[arg-type]
    ^^^^^^^^^^^^^^^^^^^^^^^^^^^^^^^^^^^^^^^^^^^^^^^^^^^
urllib3.exceptions.MaxRetryError: HTTPSConnectionPool(host='akatsuki.gg', port=443): Max retries exceeded with url: /api/v1/users/scores/first?mode=0&p=4&l=100&rx=1&id=81870 (Caused by NameResolutionError("<urllib3.connection.HTTPSConnection object at 0x00000184CCB71B50>: Failed to resolve 'akatsuki.gg' ([Errno 11001] getaddrinfo failed)"))

During handling of the above exception, another exception occurred:

Traceback (most recent call last):
  File "C:\Users\Scott\Documents\OsuCoding\osuTasks\trackFirstPlaces.py", line 103, in <module>
    main()
  File "C:\Users\Scott\Documents\OsuCoding\osuTasks\trackFirstPlaces.py", line 63, in main
    currentFirstPlaceDict = getAllFirstPlaces()
                            ^^^^^^^^^^^^^^^^^^^
  File "C:\Users\Scott\Documents\OsuCoding\osuTasks\trackFirstPlaces.py", line 41, in getAllFirstPlaces
    firstPlaces = requests.get(url).json()
                  ^^^^^^^^^^^^^^^^^
  File "C:\Users\Scott\AppData\Local\Programs\Python\Python311\Lib\site-packages\requests\api.py", line 73, in get
    return request("get", url, params=params, **kwargs)
           ^^^^^^^^^^^^^^^^^^^^^^^^^^^^^^^^^^^^^^^^^^^^
  File "C:\Users\Scott\AppData\Local\Programs\Python\Python311\Lib\site-packages\requests\api.py", line 59, in request
    return session.request(method=method, url=url, **kwargs)
           ^^^^^^^^^^^^^^^^^^^^^^^^^^^^^^^^^^^^^^^^^^^^^^^^^
  File "C:\Users\Scott\AppData\Local\Programs\Python\Python311\Lib\site-packages\requests\sessions.py", line 589, in request
    resp = self.send(prep, **send_kwargs)
           ^^^^^^^^^^^^^^^^^^^^^^^^^^^^^^
  File "C:\Users\Scott\AppData\Local\Programs\Python\Python311\Lib\site-packages\requests\sessions.py", line 703, in send
    r = adapter.send(request, **kwargs)
        ^^^^^^^^^^^^^^^^^^^^^^^^^^^^^^^
  File "C:\Users\Scott\AppData\Local\Programs\Python\Python311\Lib\site-packages\requests\adapters.py", line 700, in send
    raise ConnectionError(e, request=request)
requests.exceptions.ConnectionError: HTTPSConnectionPool(host='akatsuki.gg', port=443): Max retries exceeded with url: /api/v1/users/scores/first?mode=0&p=4&l=100&rx=1&id=81870 (Caused by NameResolutionError("<urllib3.connection.HTTPSConnection object at 0x00000184CCB71B50>: Failed to resolve 'akatsuki.gg' ([Errno 11001] getaddrinfo failed)"))
Traceback (most recent call last):
  File "C:\Users\Scott\AppData\Local\Programs\Python\Python311\Lib\site-packages\urllib3\connection.py", line 198, in _new_conn
    sock = connection.create_connection(
           ^^^^^^^^^^^^^^^^^^^^^^^^^^^^^
  File "C:\Users\Scott\AppData\Local\Programs\Python\Python311\Lib\site-packages\urllib3\util\connection.py", line 60, in create_connection
    for res in socket.getaddrinfo(host, port, family, socket.SOCK_STREAM):
               ^^^^^^^^^^^^^^^^^^^^^^^^^^^^^^^^^^^^^^^^^^^^^^^^^^^^^^^^^^
  File "C:\Users\Scott\AppData\Local\Programs\Python\Python311\Lib\socket.py", line 962, in getaddrinfo
    for res in _socket.getaddrinfo(host, port, family, type, proto, flags):
               ^^^^^^^^^^^^^^^^^^^^^^^^^^^^^^^^^^^^^^^^^^^^^^^^^^^^^^^^^^^
socket.gaierror: [Errno 11001] getaddrinfo failed

The above exception was the direct cause of the following exception:

Traceback (most recent call last):
  File "C:\Users\Scott\AppData\Local\Programs\Python\Python311\Lib\site-packages\urllib3\connectionpool.py", line 787, in urlopen
    response = self._make_request(
               ^^^^^^^^^^^^^^^^^^^
  File "C:\Users\Scott\AppData\Local\Programs\Python\Python311\Lib\site-packages\urllib3\connectionpool.py", line 488, in _make_request
    raise new_e
  File "C:\Users\Scott\AppData\Local\Programs\Python\Python311\Lib\site-packages\urllib3\connectionpool.py", line 464, in _make_request
    self._validate_conn(conn)
  File "C:\Users\Scott\AppData\Local\Programs\Python\Python311\Lib\site-packages\urllib3\connectionpool.py", line 1093, in _validate_conn
    conn.connect()
  File "C:\Users\Scott\AppData\Local\Programs\Python\Python311\Lib\site-packages\urllib3\connection.py", line 704, in connect
    self.sock = sock = self._new_conn()
                       ^^^^^^^^^^^^^^^^
  File "C:\Users\Scott\AppData\Local\Programs\Python\Python311\Lib\site-packages\urllib3\connection.py", line 205, in _new_conn
    raise NameResolutionError(self.host, self, e) from e
urllib3.exceptions.NameResolutionError: <urllib3.connection.HTTPSConnection object at 0x000001F2E4977890>: Failed to resolve 'akatsuki.gg' ([Errno 11001] getaddrinfo failed)

The above exception was the direct cause of the following exception:

Traceback (most recent call last):
  File "C:\Users\Scott\AppData\Local\Programs\Python\Python311\Lib\site-packages\requests\adapters.py", line 667, in send
    resp = conn.urlopen(
           ^^^^^^^^^^^^^
  File "C:\Users\Scott\AppData\Local\Programs\Python\Python311\Lib\site-packages\urllib3\connectionpool.py", line 841, in urlopen
    retries = retries.increment(
              ^^^^^^^^^^^^^^^^^^
  File "C:\Users\Scott\AppData\Local\Programs\Python\Python311\Lib\site-packages\urllib3\util\retry.py", line 519, in increment
    raise MaxRetryError(_pool, url, reason) from reason  # type: ignore[arg-type]
    ^^^^^^^^^^^^^^^^^^^^^^^^^^^^^^^^^^^^^^^^^^^^^^^^^^^
urllib3.exceptions.MaxRetryError: HTTPSConnectionPool(host='akatsuki.gg', port=443): Max retries exceeded with url: /api/v1/users/scores/first?mode=0&p=15&l=100&rx=1&id=81870 (Caused by NameResolutionError("<urllib3.connection.HTTPSConnection object at 0x000001F2E4977890>: Failed to resolve 'akatsuki.gg' ([Errno 11001] getaddrinfo failed)"))

During handling of the above exception, another exception occurred:

Traceback (most recent call last):
  File "C:\Users\Scott\Documents\OsuCoding\osuTasks\trackFirstPlaces.py", line 103, in <module>
    main()
  File "C:\Users\Scott\Documents\OsuCoding\osuTasks\trackFirstPlaces.py", line 63, in main
    currentFirstPlaceDict = getAllFirstPlaces()
                            ^^^^^^^^^^^^^^^^^^^
  File "C:\Users\Scott\Documents\OsuCoding\osuTasks\trackFirstPlaces.py", line 41, in getAllFirstPlaces
    firstPlaces = requests.get(url).json()
                  ^^^^^^^^^^^^^^^^^
  File "C:\Users\Scott\AppData\Local\Programs\Python\Python311\Lib\site-packages\requests\api.py", line 73, in get
    return request("get", url, params=params, **kwargs)
           ^^^^^^^^^^^^^^^^^^^^^^^^^^^^^^^^^^^^^^^^^^^^
  File "C:\Users\Scott\AppData\Local\Programs\Python\Python311\Lib\site-packages\requests\api.py", line 59, in request
    return session.request(method=method, url=url, **kwargs)
           ^^^^^^^^^^^^^^^^^^^^^^^^^^^^^^^^^^^^^^^^^^^^^^^^^
  File "C:\Users\Scott\AppData\Local\Programs\Python\Python311\Lib\site-packages\requests\sessions.py", line 589, in request
    resp = self.send(prep, **send_kwargs)
           ^^^^^^^^^^^^^^^^^^^^^^^^^^^^^^
  File "C:\Users\Scott\AppData\Local\Programs\Python\Python311\Lib\site-packages\requests\sessions.py", line 703, in send
    r = adapter.send(request, **kwargs)
        ^^^^^^^^^^^^^^^^^^^^^^^^^^^^^^^
  File "C:\Users\Scott\AppData\Local\Programs\Python\Python311\Lib\site-packages\requests\adapters.py", line 700, in send
    raise ConnectionError(e, request=request)
requests.exceptions.ConnectionError: HTTPSConnectionPool(host='akatsuki.gg', port=443): Max retries exceeded with url: /api/v1/users/scores/first?mode=0&p=15&l=100&rx=1&id=81870 (Caused by NameResolutionError("<urllib3.connection.HTTPSConnection object at 0x000001F2E4977890>: Failed to resolve 'akatsuki.gg' ([Errno 11001] getaddrinfo failed)"))
